Train on 1688114 samples, validate on 285242 samples
Epoch 1/5
1662976/1688114 [============================>.] - ETA: 0s - loss: 0.1652 - binary_crossentropy: 0.1652Epoch 00000: val_loss improved from inf to 0.11425, saving model to ../trained_models/00-0.1143.h5
Traceback (most recent call last):
  File "/usr/local/lib/python3.5/dist-packages/tensorflow/python/client/session.py", line 1136, in _do_call
    return fn(*args)
  File "/usr/local/lib/python3.5/dist-packages/tensorflow/python/client/session.py", line 1118, in _run_fn
    status, run_metadata)
  File "/usr/lib/python3.5/contextlib.py", line 66, in __exit__
    next(self.gen)
  File "/usr/local/lib/python3.5/dist-packages/tensorflow/python/framework/errors_impl.py", line 466, in raise_exception_on_not_ok_status
    pywrap_tensorflow.TF_GetCode(status))
tensorflow.python.framework.errors_impl.InvalidArgumentError: Tensor must be 4-D with last dim 1, 3, or 4, not [1,1]
	 [[Node: dense_2/bias_0_1 = ImageSummary[T=DT_FLOAT, bad_color=Tensor<type: uint8 shape: [4] values: 255 0 0...>, max_images=3, _device="/job:localhost/replica:0/task:0/cpu:0"](dense_2/bias_0_1/tag, ExpandDims_11)]]

During handling of the above exception, another exception occurred:

Traceback (most recent call last):
  File "main_DNN.py", line 246, in <module>
    batch_size=batch_size, callbacks=[checkpoint, tbCallBack])
  File "/usr/local/lib/python3.5/dist-packages/keras/models.py", line 856, in fit
    initial_epoch=initial_epoch)
  File "/usr/local/lib/python3.5/dist-packages/keras/engine/training.py", line 1498, in fit
    initial_epoch=initial_epoch)
  File "/usr/local/lib/python3.5/dist-packages/keras/engine/training.py", line 1170, in _fit_loop
    callbacks.on_epoch_end(epoch, epoch_logs)
  File "/usr/local/lib/python3.5/dist-packages/keras/callbacks.py", line 77, in on_epoch_end
    callback.on_epoch_end(epoch, logs)
  File "/usr/local/lib/python3.5/dist-packages/keras/callbacks.py", line 705, in on_epoch_end
    result = self.sess.run([self.merged], feed_dict=feed_dict)
  File "/usr/local/lib/python3.5/dist-packages/tensorflow/python/client/session.py", line 786, in run
    run_metadata_ptr)
  File "/usr/local/lib/python3.5/dist-packages/tensorflow/python/client/session.py", line 994, in _run
    feed_dict_string, options, run_metadata)
  File "/usr/local/lib/python3.5/dist-packages/tensorflow/python/client/session.py", line 1129, in _do_run
    target_list, options, run_metadata)
  File "/usr/local/lib/python3.5/dist-packages/tensorflow/python/client/session.py", line 1149, in _do_call
    raise type(e)(node_def, op, message)
tensorflow.python.framework.errors_impl.InvalidArgumentError: Tensor must be 4-D with last dim 1, 3, or 4, not [1,1]
	 [[Node: dense_2/bias_0_1 = ImageSummary[T=DT_FLOAT, bad_color=Tensor<type: uint8 shape: [4] values: 255 0 0...>, max_images=3, _device="/job:localhost/replica:0/task:0/cpu:0"](dense_2/bias_0_1/tag, ExpandDims_11)]]

Caused by op 'dense_2/bias_0_1', defined at:
  File "main_DNN.py", line 246, in <module>
    batch_size=batch_size, callbacks=[checkpoint, tbCallBack])
  File "/usr/local/lib/python3.5/dist-packages/keras/models.py", line 856, in fit
    initial_epoch=initial_epoch)
  File "/usr/local/lib/python3.5/dist-packages/keras/engine/training.py", line 1498, in fit
    initial_epoch=initial_epoch)
  File "/usr/local/lib/python3.5/dist-packages/keras/engine/training.py", line 1113, in _fit_loop
    callbacks.set_model(callback_model)
  File "/usr/local/lib/python3.5/dist-packages/keras/callbacks.py", line 52, in set_model
    callback.set_model(model)
  File "/usr/local/lib/python3.5/dist-packages/keras/callbacks.py", line 641, in set_model
    tf.summary.image(weight.name, w_img)
  File "/usr/local/lib/python3.5/dist-packages/tensorflow/python/summary/summary.py", line 184, in image
    name=scope)
  File "/usr/local/lib/python3.5/dist-packages/tensorflow/python/ops/gen_logging_ops.py", line 200, in _image_summary
    name=name)
  File "/usr/local/lib/python3.5/dist-packages/tensorflow/python/framework/op_def_library.py", line 767, in apply_op
    op_def=op_def)
  File "/usr/local/lib/python3.5/dist-packages/tensorflow/python/framework/ops.py", line 2336, in create_op
    original_op=self._default_original_op, op_def=op_def)
  File "/usr/local/lib/python3.5/dist-packages/tensorflow/python/framework/ops.py", line 1228, in __init__
    self._traceback = _extract_stack()

InvalidArgumentError (see above for traceback): Tensor must be 4-D with last dim 1, 3, or 4, not [1,1]
	 [[Node: dense_2/bias_0_1 = ImageSummary[T=DT_FLOAT, bad_color=Tensor<type: uint8 shape: [4] values: 255 0 0...>, max_images=3, _device="/job:localhost/replica:0/task:0/cpu:0"](dense_2/bias_0_1/tag, ExpandDims_11)]]

